Workbook

Sheet Dashboard
AZ1: Helper
B2: 🌱 Mochu's Monthly Productivity Dashboard | AZ2: Days in Month | BA2: =DAY(EOMONTH(DATE($E$5,MATCH($C$5,Lists!$A$2:$A$13,0),1),0)) -> 31
AZ3: Total Possible | BA3: =$B$8*$BA$2 -> 124
B4: Select Month and Year | G4: {="✨ "&INDEX(Lists!$N$2:$N$8,MOD(DAY(TODAY()),7)+1)} -> ✨ Win the day, one checkbox at a time.
B5: Month | C5: July | D5: Year | E5: 2026
B7: 📌 Total Tasks | E7: ✅ Total Completed | H7: ⏳ Total Pending | K7: 🎯 Overall Progress | N7: 📅 Today Completion | AT7: 🎯 Focus for Today
B8: =COUNTA($B$20:$B$69) -> 4 | E8: =SUM($AM$20:$AM$69) -> 5 | H8: =MAX(0,$BA$3-E8) -> 119 | K8: =IFERROR(E8/$BA$3,0) -> 0.040322581 | N8: =IFERROR(SUM(INDEX(Task_Data!$AM$2:$BQ$51,0,MATCH(TODAY(),$H$16:$AL$16,0)))/$B$8,0) -> 1
AT9: {=IFERROR(INDEX($B$20:$B$69,SMALL(IF(($B$20:$B$69<>"")*(IFERROR(INDEX(Task_Data!$AM$2:$BQ$51,0,MATCH(TODAY(),$H$16:$AL$16,0)),0)=0),ROW($B$20:$B$69)-ROW($B$20)+1),ROW(A1))),"")}
AT10: {=IFERROR(INDEX($B$20:$B$69,SMALL(IF(($B$20:$B$69<>"")*(IFERROR(INDEX(Task_Data!$AM$2:$BQ$51,0,MATCH(TODAY(),$H$16:$AL$16,0)),0)=0),ROW($B$20:$B$69)-ROW($B$20)+1),ROW(A2))),"")}
B11: 🔥 Current Streak | E11: 🏆 Longest Streak | H11: ⭐ Best Day | K11: 🌧 Weak Day | N11: ⚠️ Missed / Gap | AT11: {=IFERROR(INDEX($B$20:$B$69,SMALL(IF(($B$20:$B$69<>"")*(IFERROR(INDEX(Task_Data!$AM$2:$BQ$51,0,MATCH(TODAY(),$H$16:$AL$16,0)),0)=0),ROW($B$20:$B$69)-ROW($B$20)+1),ROW(A3))),"")}
B12: =IFERROR(MAX($AP$20:$AP$69),0) -> 2 | E12: =IFERROR(MAX($AQ$20:$AQ$69),0) -> 2 | H12: =IFERROR(TEXT(INDEX(Task_Data!$CA$1:$DE$1,1,MATCH(MAX(Task_Data!$CA$3:$DE$3),Task_Data!$CA$3:$DE$3,0)),"dd-mmm")&" ("&TEXT(MAX(Task_Data!$CA$3:$DE$3),"0%")&")","-") -> 04-Jul (100%) | K12: =IFERROR(TEXT(INDEX(Task_Data!$CA$1:$DE$1,1,MATCH(MIN(Task_Data!$CA$3:$DE$3),Task_Data!$CA$3:$DE$3,0)),"dd-mmm")&" ("&TEXT(MIN(Task_Data!$CA$3:$DE$3),"0%")&")","-") -> 01-Jul (0%) | N12: =SUM($AN$20:$AN$69) -> 61 | AT12: {=IFERROR(INDEX($B$20:$B$69,SMALL(IF(($B$20:$B$69<>"")*(IFERROR(INDEX(Task_Data!$AM$2:$BQ$51,0,MATCH(TODAY(),$H$16:$AL$16,0)),0)=0),ROW($B$20:$B$69)-ROW($B$20)+1),ROW(A4))),"")}
AT13: {=IFERROR(INDEX($B$20:$B$69,SMALL(IF(($B$20:$B$69<>"")*(IFERROR(INDEX(Task_Data!$AM$2:$BQ$51,0,MATCH(TODAY(),$H$16:$AL$16,0)),0)=0),ROW($B$20:$B$69)-ROW($B$20)+1),ROW(A5))),"")}
AT14: {=IFERROR(INDEX($B$20:$B$69,SMALL(IF(($B$20:$B$69<>"")*(IFERROR(INDEX(Task_Data!$AM$2:$BQ$51,0,MATCH(TODAY(),$H$16:$AL$16,0)),0)=0),ROW($B$20:$B$69)-ROW($B$20)+1),ROW(A6))),"")}
B15: Avg Done/Day | C15: Consistency | D15: Not Started | E15: Fully Done | F15: Most Consistent | AT15: {=IFERROR(INDEX($B$20:$B$69,SMALL(IF(($B$20:$B$69<>"")*(IFERROR(INDEX(Task_Data!$AM$2:$BQ$51,0,MATCH(TODAY(),$H$16:$AL$16,0)),0)=0),ROW($B$20:$B$69)-ROW($B$20)+1),ROW(A7))),"")}
B16: =IFERROR($E$8/$BA$2,0) -> 0.16129032 | C16: =IFERROR(AVERAGEIF($B$20:$B$69,"<>",$AO$20:$AO$69),0) -> 0.040322581 | D16: =COUNTIFS($B$20:$B$69,"<>",$AM$20:$AM$69,0) -> 0 | E16: =COUNTIFS($B$20:$B$69,"<>",$AO$20:$AO$69,1) -> 0 | F16: =IFERROR(INDEX($B$20:$B$69,MATCH(MAX($AO$20:$AO$69),$AO$20:$AO$69,0)),"-") -> Study | H16: =IF(1>$BA$2,"",DATE($E$5,MATCH($C$5,Lists!$A$2:$A$13,0),1)) -> 46204 | I16: =IF(2>$BA$2,"",DATE($E$5,MATCH($C$5,Lists!$A$2:$A$13,0),2)) -> 46205 | J16: =IF(3>$BA$2,"",DATE($E$5,MATCH($C$5,Lists!$A$2:$A$13,0),3)) -> 46206 | K16: =IF(4>$BA$2,"",DATE($E$5,MATCH($C$5,Lists!$A$2:$A$13,0),4)) -> 46207 | L16: =IF(5>$BA$2,"",DATE($E$5,MATCH($C$5,Lists!$A$2:$A$13,0),5)) -> 46208 | M16: =IF(6>$BA$2,"",DATE($E$5,MATCH($C$5,Lists!$A$2:$A$13,0),6)) -> 46209 | N16: =IF(7>$BA$2,"",DATE($E$5,MATCH($C$5,Lists!$A$2:$A$13,0),7)) -> 46210 | O16: =IF(8>$BA$2,"",DATE($E$5,MATCH($C$5,Lists!$A$2:$A$13,0),8)) -> 46211 | P16: =IF(9>$BA$2,"",DATE($E$5,MATCH($C$5,Lists!$A$2:$A$13,0),9)) -> 46212 | Q16: =IF(10>$BA$2,"",DATE($E$5,MATCH($C$5,Lists!$A$2:$A$13,0),10)) -> 46213 | R16: =IF(11>$BA$2,"",DATE($E$5,MATCH($C$5,Lists!$A$2:$A$13,0),11)) -> 46214 | S16: =IF(12>$BA$2,"",DATE($E$5,MATCH($C$5,Lists!$A$2:$A$13,0),12)) -> 46215 | T16: =IF(13>$BA$2,"",DATE($E$5,MATCH($C$5,Lists!$A$2:$A$13,0),13)) -> 46216 | U16: =IF(14>$BA$2,"",DATE($E$5,MATCH($C$5,Lists!$A$2:$A$13,0),14)) -> 46217 | V16: =IF(15>$BA$2,"",DATE($E$5,MATCH($C$5,Lists!$A$2:$A$13,0),15)) -> 46218 | W16: =IF(16>$BA$2,"",DATE($E$5,MATCH($C$5,Lists!$A$2:$A$13,0),16)) -> 46219 | X16: =IF(17>$BA$2,"",DATE($E$5,MATCH($C$5,Lists!$A$2:$A$13,0),17)) -> 46220 | Y16: =IF(18>$BA$2,"",DATE($E$5,MATCH($C$5,Lists!$A$2:$A$13,0),18)) -> 46221 | Z16: =IF(19>$BA$2,"",DATE($E$5,MATCH($C$5,Lists!$A$2:$A$13,0),19)) -> 46222 | AA16: =IF(20>$BA$2,"",DATE($E$5,MATCH($C$5,Lists!$A$2:$A$13,0),20)) -> 46223 | AB16: =IF(21>$BA$2,"",DATE($E$5,MATCH($C$5,Lists!$A$2:$A$13,0),21)) -> 46224 | AC16: =IF(22>$BA$2,"",DATE($E$5,MATCH($C$5,Lists!$A$2:$A$13,0),22)) -> 46225 | AD16: =IF(23>$BA$2,"",DATE($E$5,MATCH($C$5,Lists!$A$2:$A$13,0),23)) -> 46226 | AE16: =IF(24>$BA$2,"",DATE($E$5,MATCH($C$5,Lists!$A$2:$A$13,0),24)) -> 46227 | AF16: =IF(25>$BA$2,"",DATE($E$5,MATCH($C$5,Lists!$A$2:$A$13,0),25)) -> 46228 | AG16: =IF(26>$BA$2,"",DATE($E$5,MATCH($C$5,Lists!$A$2:$A$13,0),26)) -> 46229 | AH16: =IF(27>$BA$2,"",DATE($E$5,MATCH($C$5,Lists!$A$2:$A$13,0),27)) -> 46230 | AI16: =IF(28>$BA$2,"",DATE($E$5,MATCH($C$5,Lists!$A$2:$A$13,0),28)) -> 46231 | AJ16: =IF(29>$BA$2,"",DATE($E$5,MATCH($C$5,Lists!$A$2:$A$13,0),29)) -> 46232 | AK16: =IF(30>$BA$2,"",DATE($E$5,MATCH($C$5,Lists!$A$2:$A$13,0),30)) -> 46233 | AL16: =IF(31>$BA$2,"",DATE($E$5,MATCH($C$5,Lists!$A$2:$A$13,0),31)) -> 46234 | AT16: {=IFERROR(INDEX($B$20:$B$69,SMALL(IF(($B$20:$B$69<>"")*(IFERROR(INDEX(Task_Data!$AM$2:$BQ$51,0,MATCH(TODAY(),$H$16:$AL$16,0)),0)=0),ROW($B$20:$B$69)-ROW($B$20)+1),ROW(A8))),"")}
H17: =IF(H$16="","",DAY(H$16)) -> 1 | I17: =IF(I$16="","",DAY(I$16)) -> 2 | J17: =IF(J$16="","",DAY(J$16)) -> 3 | K17: =IF(K$16="","",DAY(K$16)) -> 4 | L17: =IF(L$16="","",DAY(L$16)) -> 5 | M17: =IF(M$16="","",DAY(M$16)) -> 6 | N17: =IF(N$16="","",DAY(N$16)) -> 7 | O17: =IF(O$16="","",DAY(O$16)) -> 8 | ... AL17: =IF(AL$16="","",DAY(AL$16)) -> 31 | AT17: {=IFERROR(INDEX($B$20:$B$69,SMALL(IF(($B$20:$B$69<>"")*(IFERROR(INDEX(Task_Data!$AM$2:$BQ$51,0,MATCH(TODAY(),$H$16:$AL$16,0)),0)=0),ROW($B$20:$B$69)-ROW($B$20)+1),ROW(A9))),"")}
H18: =IF(H$16="","",CHOOSE(WEEKDAY(H$16),"S","M","T","W","T","F","S")) -> W | I18: =IF(I$16="","",CHOOSE(WEEKDAY(I$16),"S","M","T","W","T","F","S")) -> T | J18: =IF(J$16="","",CHOOSE(WEEKDAY(J$16),"S","M","T","W","T","F","S")) -> F | K18: =IF(K$16="","",CHOOSE(WEEKDAY(K$16),"S","M","T","W","T","F","S")) -> S | L18: =IF(L$16="","",CHOOSE(WEEKDAY(L$16),"S","M","T","W","T","F","S")) -> S | M18: =IF(M$16="","",CHOOSE(WEEKDAY(M$16),"S","M","T","W","T","F","S")) -> M | N18: =IF(N$16="","",CHOOSE(WEEKDAY(N$16),"S","M","T","W","T","F","S")) -> T | O18: =IF(O$16="","",CHOOSE(WEEKDAY(O$16),"S","M","T","W","T","F","S")) -> W | ... AL18: =IF(AL$16="","",CHOOSE(WEEKDAY(AL$16),"S","M","T","W","T","F","S")) -> F | AT18: {=IFERROR(INDEX($B$20:$B$69,SMALL(IF(($B$20:$B$69<>"")*(IFERROR(INDEX(Task_Data!$AM$2:$BQ$51,0,MATCH(TODAY(),$H$16:$AL$16,0)),0)=0),ROW($B$20:$B$69)-ROW($B$20)+1),ROW(A10))),"")}
B19: Task Name | C19: Priority | D19: Category | E19: Frequency | F19: Target | G19: Notes | AM19: Actual Done | AN19: Gap | AO19: Completion % | AP19: Current Streak | AQ19: Longest Streak | AR19: Score | AT19: {=IFERROR(INDEX($B$20:$B$69,SMALL(IF(($B$20:$B$69<>"")*(IFERROR(INDEX(Task_Data!$AM$2:$BQ$51,0,MATCH(TODAY(),$H$16:$AL$16,0)),0)=0),ROW($B$20:$B$69)-ROW($B$20)+1),ROW(A11))),"")}
B20: Exercise | C20: High | D20: Health | E20: Weekly | F20: 25 | G20: Morning walk or workout | H20: FALSE | I20: FALSE | J20: FALSE | K20: FALSE | L20: FALSE | M20: FALSE | N20: FALSE | O20: FALSE | P20: FALSE | Q20: FALSE | R20: FALSE | S20: FALSE | T20: FALSE | U20: FALSE | V20: FALSE | W20: FALSE | X20: FALSE | Y20: FALSE | Z20: FALSE | AA20: FALSE | AB20: FALSE | AC20: FALSE | AD20: FALSE | AE20: FALSE | AF20: FALSE | AG20: FALSE | AH20: FALSE | AI20: FALSE | AJ20: FALSE | AK20: FALSE | AL20: FALSE | AM20: =IF($B20="","",SUM(Task_Data!AM2:BQ2)) -> 1 | AN20: =IF($B20="","",MAX(0,$F20-AM20)) -> 24 | AO20: =IF($B20="","",IFERROR(AM20/$BA$2,0)) -> 0.032258065 | AP20: =IF($B20="","",MIN(AQ20,COUNTIF(Task_Data!AM2:BQ2,1))) -> 1 | AQ20: =IF($B20="","",Task_Data!BT2) -> 1 | AR20: {=IF($B20="","",ROUND(AO20*60+_xlfn.SWITCH($C20,"High",25,"Medium",18,"Low",12,0)+IFERROR(AQ20/$BA$2,0)*15,1))} -> 27.4
B21: Study | C21: High | D21: Study | E21: Daily | F21: 20 | G21: Interview practice | H21: FALSE | I21: FALSE | J21: FALSE | K21: FALSE | L21: FALSE | M21: FALSE | N21: FALSE | O21: FALSE | P21: FALSE | Q21: FALSE | R21: FALSE | S21: FALSE | T21: FALSE | U21: FALSE | V21: FALSE | W21: FALSE | X21: FALSE | Y21: FALSE | Z21: FALSE | AA21: FALSE | AB21: FALSE | AC21: FALSE | AD21: FALSE | AE21: FALSE | AF21: FALSE | AG21: FALSE | AH21: FALSE | AI21: FALSE | AJ21: FALSE | AK21: FALSE | AL21: FALSE | AM21: =IF($B21="","",SUM(Task_Data!AM3:BQ3)) -> 2 | AN21: =IF($B21="","",MAX(0,$F21-AM21)) -> 18 | AO21: =IF($B21="","",IFERROR(AM21/$BA$2,0)) -> 0.064516129 | AP21: =IF($B21="","",MIN(AQ21,COUNTIF(Task_Data!AM3:BQ3,1))) -> 2 | AQ21: =IF($B21="","",Task_Data!BT3) -> 2 | AR21: {=IF($B21="","",ROUND(AO21*60+_xlfn.SWITCH($C21,"High",25,"Medium",18,"Low",12,0)+IFERROR(AQ21/$BA$2,0)*15,1))} -> 29.8
B22: Read Book | C22: Medium | D22: Habit | E22: Daily | F22: 15 | G22: 15 pages | H22: FALSE | I22: FALSE | J22: FALSE | K22: FALSE | L22: FALSE | M22: FALSE | N22: FALSE | O22: FALSE | P22: FALSE | Q22: FALSE | R22: FALSE | S22: FALSE | T22: FALSE | U22: FALSE | V22: FALSE | W22: FALSE | X22: FALSE | Y22: FALSE | Z22: FALSE | AA22: FALSE | AB22: FALSE | AC22: FALSE | AD22: FALSE | AE22: FALSE | AF22: FALSE | AG22: FALSE | AH22: FALSE | AI22: FALSE | AJ22: FALSE | AK22: FALSE | AL22: FALSE | AM22: =IF($B22="","",SUM(Task_Data!AM4:BQ4)) -> 1 | AN22: =IF($B22="","",MAX(0,$F22-AM22)) -> 14 | AO22: =IF($B22="","",IFERROR(AM22/$BA$2,0)) -> 0.032258065 | AP22: =IF($B22="","",MIN(AQ22,COUNTIF(Task_Data!AM4:BQ4,1))) -> 1 | AQ22: =IF($B22="","",Task_Data!BT4) -> 1 | AR22: {=IF($B22="","",ROUND(AO22*60+_xlfn.SWITCH($C22,"High",25,"Medium",18,"Low",12,0)+IFERROR(AQ22/$BA$2,0)*15,1))} -> 20.4
B23: Call Family | C23: Low | D23: Personal | E23: Weekly | F23: 6 | G23: Stay connected | H23: FALSE | I23: FALSE | J23: FALSE | K23: FALSE | L23: FALSE | M23: FALSE | N23: FALSE | O23: FALSE | P23: FALSE | Q23: FALSE | R23: FALSE | S23: FALSE | T23: FALSE | U23: FALSE | V23: FALSE | W23: FALSE | X23: FALSE | Y23: FALSE | Z23: FALSE | AA23: FALSE | AB23: FALSE | AC23: FALSE | AD23: FALSE | AE23: FALSE | AF23: FALSE | AG23: FALSE | AH23: FALSE | AI23: FALSE | AJ23: FALSE | AK23: FALSE | AL23: FALSE | AM23: =IF($B23="","",SUM(Task_Data!AM5:BQ5)) -> 1 | AN23: =IF($B23="","",MAX(0,$F23-AM23)) -> 5 | AO23: =IF($B23="","",IFERROR(AM23/$BA$2,0)) -> 0.032258065 | AP23: =IF($B23="","",MIN(AQ23,COUNTIF(Task_Data!AM5:BQ5,1))) -> 1 | AQ23: =IF($B23="","",Task_Data!BT5) -> 1 | AR23: {=IF($B23="","",ROUND(AO23*60+_xlfn.SWITCH($C23,"High",25,"Medium",18,"Low",12,0)+IFERROR(AQ23/$BA$2,0)*15,1))} -> 14.4 | AT23: ⭐ Top 3 Priorities
H24: FALSE | I24: FALSE | J24: FALSE | K24: FALSE | L24: FALSE | M24: FALSE | N24: FALSE | O24: FALSE | P24: FALSE | Q24: FALSE | R24: FALSE | S24: FALSE | T24: FALSE | U24: FALSE | V24: FALSE | W24: FALSE | X24: FALSE | Y24: FALSE | Z24: FALSE | AA24: FALSE | AB24: FALSE | AC24: FALSE | AD24: FALSE | AE24: FALSE | AF24: FALSE | AG24: FALSE | AH24: FALSE | AI24: FALSE | AJ24: FALSE | AK24: FALSE | AL24: FALSE | AM24: =IF($B24="","",SUM(Task_Data!AM6:BQ6)) | AN24: =IF($B24="","",MAX(0,$F24-AM24)) | AO24: =IF($B24="","",IFERROR(AM24/$BA$2,0)) | AP24: =IF($B24="","",MIN(AQ24,COUNTIF(Task_Data!AM6:BQ6,1))) | AQ24: =IF($B24="","",Task_Data!BT6) | AR24: {=IF($B24="","",ROUND(AO24*60+_xlfn.SWITCH($C24,"High",25,"Medium",18,"Low",12,0)+IFERROR(AQ24/$BA$2,0)*15,1))}
H25: FALSE | I25: FALSE | J25: FALSE | K25: FALSE | L25: FALSE | M25: FALSE | N25: FALSE | O25: FALSE | P25: FALSE | Q25: FALSE | R25: FALSE | S25: FALSE | T25: FALSE | U25: FALSE | V25: FALSE | W25: FALSE | X25: FALSE | Y25: FALSE | Z25: FALSE | AA25: FALSE | AB25: FALSE | AC25: FALSE | AD25: FALSE | AE25: FALSE | AF25: FALSE | AG25: FALSE | AH25: FALSE | AI25: FALSE | AJ25: FALSE | AK25: FALSE | AL25: FALSE | AM25: =IF($B25="","",SUM(Task_Data!AM7:BQ7)) | AN25: =IF($B25="","",MAX(0,$F25-AM25)) | AO25: =IF($B25="","",IFERROR(AM25/$BA$2,0)) | AP25: =IF($B25="","",MIN(AQ25,COUNTIF(Task_Data!AM7:BQ7,1))) | AQ25: =IF($B25="","",Task_Data!BT7) | AR25: {=IF($B25="","",ROUND(AO25*60+_xlfn.SWITCH($C25,"High",25,"Medium",18,"Low",12,0)+IFERROR(AQ25/$BA$2,0)*15,1))} | AT25: {=IFERROR(INDEX($B$20:$B$69,SMALL(IF(($B$20:$B$69<>"")*($C$20:$C$69="High"),ROW($B$20:$B$69)-ROW($B$20)+1),ROW(A1))),"")} -> Exercise
H26: FALSE | I26: FALSE | J26: FALSE | K26: FALSE | L26: FALSE | M26: FALSE | N26: FALSE | O26: FALSE | P26: FALSE | Q26: FALSE | R26: FALSE | S26: FALSE | T26: FALSE | U26: FALSE | V26: FALSE | W26: FALSE | X26: FALSE | Y26: FALSE | Z26: FALSE | AA26: FALSE | AB26: FALSE | AC26: FALSE | AD26: FALSE | AE26: FALSE | AF26: FALSE | AG26: FALSE | AH26: FALSE | AI26: FALSE | AJ26: FALSE | AK26: FALSE | AL26: FALSE | AM26: =IF($B26="","",SUM(Task_Data!AM8:BQ8)) | AN26: =IF($B26="","",MAX(0,$F26-AM26)) | AO26: =IF($B26="","",IFERROR(AM26/$BA$2,0)) | AP26: =IF($B26="","",MIN(AQ26,COUNTIF(Task_Data!AM8:BQ8,1))) | AQ26: =IF($B26="","",Task_Data!BT8) | AR26: {=IF($B26="","",ROUND(AO26*60+_xlfn.SWITCH($C26,"High",25,"Medium",18,"Low",12,0)+IFERROR(AQ26/$BA$2,0)*15,1))} | AT26: {=IFERROR(INDEX($B$20:$B$69,SMALL(IF(($B$20:$B$69<>"")*($C$20:$C$69="High"),ROW($B$20:$B$69)-ROW($B$20)+1),ROW(A2))),"")} -> Study
H27: FALSE | I27: FALSE | J27: FALSE | K27: FALSE | L27: FALSE | M27: FALSE | N27: FALSE | O27: FALSE | P27: FALSE | Q27: FALSE | R27: FALSE | S27: FALSE | T27: FALSE | U27: FALSE | V27: FALSE | W27: FALSE | X27: FALSE | Y27: FALSE | Z27: FALSE | AA27: FALSE | AB27: FALSE | AC27: FALSE | AD27: FALSE | AE27: FALSE | AF27: FALSE | AG27: FALSE | AH27: FALSE | AI27: FALSE | AJ27: FALSE | AK27: FALSE | AL27: FALSE | AM27: =IF($B27="","",SUM(Task_Data!AM9:BQ9)) | AN27: =IF($B27="","",MAX(0,$F27-AM27)) | AO27: =IF($B27="","",IFERROR(AM27/$BA$2,0)) | AP27: =IF($B27="","",MIN(AQ27,COUNTIF(Task_Data!AM9:BQ9,1))) | AQ27: =IF($B27="","",Task_Data!BT9) | AR27: {=IF($B27="","",ROUND(AO27*60+_xlfn.SWITCH($C27,"High",25,"Medium",18,"Low",12,0)+IFERROR(AQ27/$BA$2,0)*15,1))} | AT27: {=IFERROR(INDEX($B$20:$B$69,SMALL(IF(($B$20:$B$69<>"")*($C$20:$C$69="High"),ROW($B$20:$B$69)-ROW($B$20)+1),ROW(A3))),"")}
H28: FALSE | I28: FALSE | J28: FALSE | K28: FALSE | L28: FALSE | M28: FALSE | N28: FALSE | O28: FALSE | P28: FALSE | Q28: FALSE | R28: FALSE | S28: FALSE | T28: FALSE | U28: FALSE | V28: FALSE | W28: FALSE | X28: FALSE | Y28: FALSE | Z28: FALSE | AA28: FALSE | AB28: FALSE | AC28: FALSE | AD28: FALSE | AE28: FALSE | AF28: FALSE | AG28: FALSE | AH28: FALSE | AI28: FALSE | AJ28: FALSE | AK28: FALSE | AL28: FALSE | AM28: =IF($B28="","",SUM(Task_Data!AM10:BQ10)) | AN28: =IF($B28="","",MAX(0,$F28-AM28)) | AO28: =IF($B28="","",IFERROR(AM28/$BA$2,0)) | AP28: =IF($B28="","",MIN(AQ28,COUNTIF(Task_Data!AM10:BQ10,1))) | AQ28: =IF($B28="","",Task_Data!BT10) | AR28: {=IF($B28="","",ROUND(AO28*60+_xlfn.SWITCH($C28,"High",25,"Medium",18,"Low",12,0)+IFERROR(AQ28/$BA$2,0)*15,1))} | AT28: {=IFERROR(INDEX($B$20:$B$69,SMALL(IF(($B$20:$B$69<>"")*($C$20:$C$69="High"),ROW($B$20:$B$69)-ROW($B$20)+1),ROW(A4))),"")}
H29: FALSE | I29: FALSE | J29: FALSE | K29: FALSE | L29: FALSE | M29: FALSE | N29: FALSE | O29: FALSE | P29: FALSE | Q29: FALSE | R29: FALSE | S29: FALSE | T29: FALSE | U29: FALSE | V29: FALSE | W29: FALSE | X29: FALSE | Y29: FALSE | Z29: FALSE | AA29: FALSE | AB29: FALSE | AC29: FALSE | AD29: FALSE | AE29: FALSE | AF29: FALSE | AG29: FALSE | AH29: FALSE | AI29: FALSE | AJ29: FALSE | AK29: FALSE | AL29: FALSE | AM29: =IF($B29="","",SUM(Task_Data!AM11:BQ11)) | AN29: =IF($B29="","",MAX(0,$F29-AM29)) | AO29: =IF($B29="","",IFERROR(AM29/$BA$2,0)) | AP29: =IF($B29="","",MIN(AQ29,COUNTIF(Task_Data!AM11:BQ11,1))) | AQ29: =IF($B29="","",Task_Data!BT11) | AR29: {=IF($B29="","",ROUND(AO29*60+_xlfn.SWITCH($C29,"High",25,"Medium",18,"Low",12,0)+IFERROR(AQ29/$BA$2,0)*15,1))} | AT29: {=IFERROR(INDEX($B$20:$B$69,SMALL(IF(($B$20:$B$69<>"")*($C$20:$C$69="High"),ROW($B$20:$B$69)-ROW($B$20)+1),ROW(A5))),"")}
H30: FALSE | I30: FALSE | J30: FALSE | K30: FALSE | L30: FALSE | M30: FALSE | N30: FALSE | O30: FALSE | P30: FALSE | Q30: FALSE | R30: FALSE | S30: FALSE | T30: FALSE | U30: FALSE | V30: FALSE | W30: FALSE | X30: FALSE | Y30: FALSE | Z30: FALSE | AA30: FALSE | AB30: FALSE | AC30: FALSE | AD30: FALSE | AE30: FALSE | AF30: FALSE | AG30: FALSE | AH30: FALSE | AI30: FALSE | AJ30: FALSE | AK30: FALSE | AL30: FALSE | AM30: =IF($B30="","",SUM(Task_Data!AM12:BQ12)) | AN30: =IF($B30="","",MAX(0,$F30-AM30)) | AO30: =IF($B30="","",IFERROR(AM30/$BA$2,0)) | AP30: =IF($B30="","",MIN(AQ30,COUNTIF(Task_Data!AM12:BQ12,1))) | AQ30: =IF($B30="","",Task_Data!BT12) | AR30: {=IF($B30="","",ROUND(AO30*60+_xlfn.SWITCH($C30,"High",25,"Medium",18,"Low",12,0)+IFERROR(AQ30/$BA$2,0)*15,1))}
H31: FALSE | I31: FALSE | J31: FALSE | K31: FALSE | L31: FALSE | M31: FALSE | N31: FALSE | O31: FALSE | P31: FALSE | Q31: FALSE | R31: FALSE | S31: FALSE | T31: FALSE | U31: FALSE | V31: FALSE | W31: FALSE | X31: FALSE | Y31: FALSE | Z31: FALSE | AA31: FALSE | AB31: FALSE | AC31: FALSE | AD31: FALSE | AE31: FALSE | AF31: FALSE | AG31: FALSE | AH31: FALSE | AI31: FALSE | AJ31: FALSE | AK31: FALSE | AL31: FALSE | AM31: =IF($B31="","",SUM(Task_Data!AM13:BQ13)) | AN31: =IF($B31="","",MAX(0,$F31-AM31)) | AO31: =IF($B31="","",IFERROR(AM31/$BA$2,0)) | AP31: =IF($B31="","",MIN(AQ31,COUNTIF(Task_Data!AM13:BQ13,1))) | AQ31: =IF($B31="","",Task_Data!BT13) | AR31: {=IF($B31="","",ROUND(AO31*60+_xlfn.SWITCH($C31,"High",25,"Medium",18,"Low",12,0)+IFERROR(AQ31/$BA$2,0)*15,1))}
H32: FALSE | I32: FALSE | J32: FALSE | K32: FALSE | L32: FALSE | M32: FALSE | N32: FALSE | O32: FALSE | P32: FALSE | Q32: FALSE | R32: FALSE | S32: FALSE | T32: FALSE | U32: FALSE | V32: FALSE | W32: FALSE | X32: FALSE | Y32: FALSE | Z32: FALSE | AA32: FALSE | AB32: FALSE | AC32: FALSE | AD32: FALSE | AE32: FALSE | AF32: FALSE | AG32: FALSE | AH32: FALSE | AI32: FALSE | AJ32: FALSE | AK32: FALSE | AL32: FALSE | AM32: =IF($B32="","",SUM(Task_Data!AM14:BQ14)) | AN32: =IF($B32="","",MAX(0,$F32-AM32)) | AO32: =IF($B32="","",IFERROR(AM32/$BA$2,0)) | AP32: =IF($B32="","",MIN(AQ32,COUNTIF(Task_Data!AM14:BQ14,1))) | AQ32: =IF($B32="","",Task_Data!BT14) | AR32: {=IF($B32="","",ROUND(AO32*60+_xlfn.SWITCH($C32,"High",25,"Medium",18,"Low",12,0)+IFERROR(AQ32/$BA$2,0)*15,1))}
H33: FALSE | I33: FALSE | J33: FALSE | K33: FALSE | L33: FALSE | M33: FALSE | N33: FALSE | O33: FALSE | P33: FALSE | Q33: FALSE | R33: FALSE | S33: FALSE | T33: FALSE | U33: FALSE | V33: FALSE | W33: FALSE | X33: FALSE | Y33: FALSE | Z33: FALSE | AA33: FALSE | AB33: FALSE | AC33: FALSE | AD33: FALSE | AE33: FALSE | AF33: FALSE | AG33: FALSE | AH33: FALSE | AI33: FALSE | AJ33: FALSE | AK33: FALSE | AL33: FALSE | AM33: =IF($B33="","",SUM(Task_Data!AM15:BQ15)) | AN33: =IF($B33="","",MAX(0,$F33-AM33)) | AO33: =IF($B33="","",IFERROR(AM33/$BA$2,0)) | AP33: =IF($B33="","",MIN(AQ33,COUNTIF(Task_Data!AM15:BQ15,1))) | AQ33: =IF($B33="","",Task_Data!BT15) | AR33: {=IF($B33="","",ROUND(AO33*60+_xlfn.SWITCH($C33,"High",25,"Medium",18,"Low",12,0)+IFERROR(AQ33/$BA$2,0)*15,1))} | AT33: ⚠️ Tasks Falling Behind
H34: FALSE | I34: FALSE | J34: FALSE | K34: FALSE | L34: FALSE | M34: FALSE | N34: FALSE | O34: FALSE | P34: FALSE | Q34: FALSE | R34: FALSE | S34: FALSE | T34: FALSE | U34: FALSE | V34: FALSE | W34: FALSE | X34: FALSE | Y34: FALSE | Z34: FALSE | AA34: FALSE | AB34: FALSE | AC34: FALSE | AD34: FALSE | AE34: FALSE | AF34: FALSE | AG34: FALSE | AH34: FALSE | AI34: FALSE | AJ34: FALSE | AK34: FALSE | AL34: FALSE | AM34: =IF($B34="","",SUM(Task_Data!AM16:BQ16)) | AN34: =IF($B34="","",MAX(0,$F34-AM34)) | AO34: =IF($B34="","",IFERROR(AM34/$BA$2,0)) | AP34: =IF($B34="","",MIN(AQ34,COUNTIF(Task_Data!AM16:BQ16,1))) | AQ34: =IF($B34="","",Task_Data!BT16) | AR34: {=IF($B34="","",ROUND(AO34*60+_xlfn.SWITCH($C34,"High",25,"Medium",18,"Low",12,0)+IFERROR(AQ34/$BA$2,0)*15,1))}
H35: FALSE | I35: FALSE | J35: FALSE | K35: FALSE | L35: FALSE | M35: FALSE | N35: FALSE | O35: FALSE | P35: FALSE | Q35: FALSE | R35: FALSE | S35: FALSE | T35: FALSE | U35: FALSE | V35: FALSE | W35: FALSE | X35: FALSE | Y35: FALSE | Z35: FALSE | AA35: FALSE | AB35: FALSE | AC35: FALSE | AD35: FALSE | AE35: FALSE | AF35: FALSE | AG35: FALSE | AH35: FALSE | AI35: FALSE | AJ35: FALSE | AK35: FALSE | AL35: FALSE | AM35: =IF($B35="","",SUM(Task_Data!AM17:BQ17)) | AN35: =IF($B35="","",MAX(0,$F35-AM35)) | AO35: =IF($B35="","",IFERROR(AM35/$BA$2,0)) | AP35: =IF($B35="","",MIN(AQ35,COUNTIF(Task_Data!AM17:BQ17,1))) | AQ35: =IF($B35="","",Task_Data!BT17) | AR35: {=IF($B35="","",ROUND(AO35*60+_xlfn.SWITCH($C35,"High",25,"Medium",18,"Low",12,0)+IFERROR(AQ35/$BA$2,0)*15,1))} | AT35: {=IFERROR(INDEX($B$20:$B$69,SMALL(IF(($B$20:$B$69<>"")*($AN$20:$AN$69>0),ROW($B$20:$B$69)-ROW($B$20)+1),ROW(A1))),"")} -> Exercise
H36: FALSE | I36: FALSE | J36: FALSE | K36: FALSE | L36: FALSE | M36: FALSE | N36: FALSE | O36: FALSE | P36: FALSE | Q36: FALSE | R36: FALSE | S36: FALSE | T36: FALSE | U36: FALSE | V36: FALSE | W36: FALSE | X36: FALSE | Y36: FALSE | Z36: FALSE | AA36: FALSE | AB36: FALSE | AC36: FALSE | AD36: FALSE | AE36: FALSE | AF36: FALSE | AG36: FALSE | AH36: FALSE | AI36: FALSE | AJ36: FALSE | AK36: FALSE | AL36: FALSE | AM36: =IF($B36="","",SUM(Task_Data!AM18:BQ18)) | AN36: =IF($B36="","",MAX(0,$F36-AM36)) | AO36: =IF($B36="","",IFERROR(AM36/$BA$2,0)) | AP36: =IF($B36="","",MIN(AQ36,COUNTIF(Task_Data!AM18:BQ18,1))) | AQ36: =IF($B36="","",Task_Data!BT18) | AR36: {=IF($B36="","",ROUND(AO36*60+_xlfn.SWITCH($C36,"High",25,"Medium",18,"Low",12,0)+IFERROR(AQ36/$BA$2,0)*15,1))} | AT36: {=IFERROR(INDEX($B$20:$B$69,SMALL(IF(($B$20:$B$69<>"")*($AN$20:$AN$69>0),ROW($B$20:$B$69)-ROW($B$20)+1),ROW(A2))),"")} -> Study
H37: FALSE | I37: FALSE | J37: FALSE | K37: FALSE | L37: FALSE | M37: FALSE | N37: FALSE | O37: FALSE | P37: FALSE | Q37: FALSE | R37: FALSE | S37: FALSE | T37: FALSE | U37: FALSE | V37: FALSE | W37: FALSE | X37: FALSE | Y37: FALSE | Z37: FALSE | AA37: FALSE | AB37: FALSE | AC37: FALSE | AD37: FALSE | AE37: FALSE | AF37: FALSE | AG37: FALSE | AH37: FALSE | AI37: FALSE | AJ37: FALSE | AK37: FALSE | AL37: FALSE | AM37: =IF($B37="","",SUM(Task_Data!AM19:BQ19)) | AN37: =IF($B37="","",MAX(0,$F37-AM37)) | AO37: =IF($B37="","",IFERROR(AM37/$BA$2,0)) | AP37: =IF($B37="","",MIN(AQ37,COUNTIF(Task_Data!AM19:BQ19,1))) | AQ37: =IF($B37="","",Task_Data!BT19) | AR37: {=IF($B37="","",ROUND(AO37*60+_xlfn.SWITCH($C37,"High",25,"Medium",18,"Low",12,0)+IFERROR(AQ37/$BA$2,0)*15,1))} | AT37: {=IFERROR(INDEX($B$20:$B$69,SMALL(IF(($B$20:$B$69<>"")*($AN$20:$AN$69>0),ROW($B$20:$B$69)-ROW($B$20)+1),ROW(A3))),"")} -> Read Book
H38: FALSE | I38: FALSE | J38: FALSE | K38: FALSE | L38: FALSE | M38: FALSE | N38: FALSE | O38: FALSE | P38: FALSE | Q38: FALSE | R38: FALSE | S38: FALSE | T38: FALSE | U38: FALSE | V38: FALSE | W38: FALSE | X38: FALSE | Y38: FALSE | Z38: FALSE | AA38: FALSE | AB38: FALSE | AC38: FALSE | AD38: FALSE | AE38: FALSE | AF38: FALSE | AG38: FALSE | AH38: FALSE | AI38: FALSE | AJ38: FALSE | AK38: FALSE | AL38: FALSE | AM38: =IF($B38="","",SUM(Task_Data!AM20:BQ20)) | AN38: =IF($B38="","",MAX(0,$F38-AM38)) | AO38: =IF($B38="","",IFERROR(AM38/$BA$2,0)) | AP38: =IF($B38="","",MIN(AQ38,COUNTIF(Task_Data!AM20:BQ20,1))) | AQ38: =IF($B38="","",Task_Data!BT20) | AR38: {=IF($B38="","",ROUND(AO38*60+_xlfn.SWITCH($C38,"High",25,"Medium",18,"Low",12,0)+IFERROR(AQ38/$BA$2,0)*15,1))} | AT38: {=IFERROR(INDEX($B$20:$B$69,SMALL(IF(($B$20:$B$69<>"")*($AN$20:$AN$69>0),ROW($B$20:$B$69)-ROW($B$20)+1),ROW(A4))),"")} -> Call Family
H39: FALSE | I39: FALSE | J39: FALSE | K39: FALSE | L39: FALSE | M39: FALSE | N39: FALSE | O39: FALSE | P39: FALSE | Q39: FALSE | R39: FALSE | S39: FALSE | T39: FALSE | U39: FALSE | V39: FALSE | W39: FALSE | X39: FALSE | Y39: FALSE | Z39: FALSE | AA39: FALSE | AB39: FALSE | AC39: FALSE | AD39: FALSE | AE39: FALSE | AF39: FALSE | AG39: FALSE | AH39: FALSE | AI39: FALSE | AJ39: FALSE | AK39: FALSE | AL39: FALSE | AM39: =IF($B39="","",SUM(Task_Data!AM21:BQ21)) | AN39: =IF($B39="","",MAX(0,$F39-AM39)) | AO39: =IF($B39="","",IFERROR(AM39/$BA$2,0)) | AP39: =IF($B39="","",MIN(AQ39,COUNTIF(Task_Data!AM21:BQ21,1))) | AQ39: =IF($B39="","",Task_Data!BT21) | AR39: {=IF($B39="","",ROUND(AO39*60+_xlfn.SWITCH($C39,"High",25,"Medium",18,"Low",12,0)+IFERROR(AQ39/$BA$2,0)*15,1))} | AT39: {=IFERROR(INDEX($B$20:$B$69,SMALL(IF(($B$20:$B$69<>"")*($AN$20:$AN$69>0),ROW($B$20:$B$69)-ROW($B$20)+1),ROW(A5))),"")}
H40: FALSE | I40: FALSE | J40: FALSE | K40: FALSE | L40: FALSE | M40: FALSE | N40: FALSE | O40: FALSE | P40: FALSE | Q40: FALSE | R40: FALSE | S40: FALSE | T40: FALSE | U40: FALSE | V40: FALSE | W40: FALSE | X40: FALSE | Y40: FALSE | Z40: FALSE | AA40: FALSE | AB40: FALSE | AC40: FALSE | AD40: FALSE | AE40: FALSE | AF40: FALSE | AG40: FALSE | AH40: FALSE | AI40: FALSE | AJ40: FALSE | AK40: FALSE | AL40: FALSE | AM40: =IF($B40="","",SUM(Task_Data!AM22:BQ22)) | AN40: =IF($B40="","",MAX(0,$F40-AM40)) | AO40: =IF($B40="","",IFERROR(AM40/$BA$2,0)) | AP40: =IF($B40="","",MIN(AQ40,COUNTIF(Task_Data!AM22:BQ22,1))) | AQ40: =IF($B40="","",Task_Data!BT22) | AR40: {=IF($B40="","",ROUND(AO40*60+_xlfn.SWITCH($C40,"High",25,"Medium",18,"Low",12,0)+IFERROR(AQ40/$BA$2,0)*15,1))} | AT40: {=IFERROR(INDEX($B$20:$B$69,SMALL(IF(($B$20:$B$69<>"")*($AN$20:$AN$69>0),ROW($B$20:$B$69)-ROW($B$20)+1),ROW(A6))),"")}
H41: FALSE | I41: FALSE | J41: FALSE | K41: FALSE | L41: FALSE | M41: FALSE | N41: FALSE | O41: FALSE | P41: FALSE | Q41: FALSE | R41: FALSE | S41: FALSE | T41: FALSE | U41: FALSE | V41: FALSE | W41: FALSE | X41: FALSE | Y41: FALSE | Z41: FALSE | AA41: FALSE | AB41: FALSE | AC41: FALSE | AD41: FALSE | AE41: FALSE | AF41: FALSE | AG41: FALSE | AH41: FALSE | AI41: FALSE | AJ41: FALSE | AK41: FALSE | AL41: FALSE | AM41: =IF($B41="","",SUM(Task_Data!AM23:BQ23)) | AN41: =IF($B41="","",MAX(0,$F41-AM41)) | AO41: =IF($B41="","",IFERROR(AM41/$BA$2,0)) | AP41: =IF($B41="","",MIN(AQ41,COUNTIF(Task_Data!AM23:BQ23,1))) | AQ41: =IF($B41="","",Task_Data!BT23) | AR41: {=IF($B41="","",ROUND(AO41*60+_xlfn.SWITCH($C41,"High",25,"Medium",18,"Low",12,0)+IFERROR(AQ41/$BA$2,0)*15,1))} | AT41: {=IFERROR(INDEX($B$20:$B$69,SMALL(IF(($B$20:$B$69<>"")*($AN$20:$AN$69>0),ROW($B$20:$B$69)-ROW($B$20)+1),ROW(A7))),"")}
...

Sheet Task_Data
A1: Task Name | B1: Priority | C1: Category | D1: Frequency | E1: Target | F1: Notes | H1: =IF(1>$BA$2,"",DATE($E$5,MATCH($C$5,Lists!$A$2:$A$13,0),1)) | I1: =IF(2>$BA$2,"",DATE($E$5,MATCH($C$5,Lists!$A$2:$A$13,0),2)) | J1: =IF(3>$BA$2,"",DATE($E$5,MATCH($C$5,Lists!$A$2:$A$13,0),3)) | K1: =IF(4>$BA$2,"",DATE($E$5,MATCH($C$5,Lists!$A$2:$A$13,0),4)) | L1: =IF(5>$BA$2,"",DATE($E$5,MATCH($C$5,Lists!$A$2:$A$13,0),5)) | M1: =IF(6>$BA$2,"",DATE($E$5,MATCH($C$5,Lists!$A$2:$A$13,0),6)) | N1: =IF(7>$BA$2,"",DATE($E$5,MATCH($C$5,Lists!$A$2:$A$13,0),7)) | O1: =IF(8>$BA$2,"",DATE($E$5,MATCH($C$5,Lists!$A$2:$A$13,0),8)) | P1: =IF(9>$BA$2,"",DATE($E$5,MATCH($C$5,Lists!$A$2:$A$13,0),9)) | Q1: =IF(10>$BA$2,"",DATE($E$5,MATCH($C$5,Lists!$A$2:$A$13,0),10)) | R1: =IF(11>$BA$2,"",DATE($E$5,MATCH($C$5,Lists!$A$2:$A$13,0),11)) | S1: =IF(12>$BA$2,"",DATE($E$5,MATCH($C$5,Lists!$A$2:$A$13,0),12)) | T1: =IF(13>$BA$2,"",DATE($E$5,MATCH($C$5,Lists!$A$2:$A$13,0),13)) | U1: =IF(14>$BA$2,"",DATE($E$5,MATCH($C$5,Lists!$A$2:$A$13,0),14)) | V1: =IF(15>$BA$2,"",DATE($E$5,MATCH($C$5,Lists!$A$2:$A$13,0),15)) | W1: =IF(16>$BA$2,"",DATE($E$5,MATCH($C$5,Lists!$A$2:$A$13,0),16)) | X1: =IF(17>$BA$2,"",DATE($E$5,MATCH($C$5,Lists!$A$2:$A$13,0),17)) | Y1: =IF(18>$BA$2,"",DATE($E$5,MATCH($C$5,Lists!$A$2:$A$13,0),18)) | Z1: =IF(19>$BA$2,"",DATE($E$5,MATCH($C$5,Lists!$A$2:$A$13,0),19)) | AA1: =IF(20>$BA$2,"",DATE($E$5,MATCH($C$5,Lists!$A$2:$A$13,0),20)) | AB1: =IF(21>$BA$2,"",DATE($E$5,MATCH($C$5,Lists!$A$2:$A$13,0),21)) | AC1: =IF(22>$BA$2,"",DATE($E$5,MATCH($C$5,Lists!$A$2:$A$13,0),22)) | AD1: =IF(23>$BA$2,"",DATE($E$5,MATCH($C$5,Lists!$A$2:$A$13,0),23)) | AE1: =IF(24>$BA$2,"",DATE($E$5,MATCH($C$5,Lists!$A$2:$A$13,0),24)) | AF1: =IF(25>$BA$2,"",DATE($E$5,MATCH($C$5,Lists!$A$2:$A$13,0),25)) | AG1: =IF(26>$BA$2,"",DATE($E$5,MATCH($C$5,Lists!$A$2:$A$13,0),26)) | AH1: =IF(27>$BA$2,"",DATE($E$5,MATCH($C$5,Lists!$A$2:$A$13,0),27)) | AI1: =IF(28>$BA$2,"",DATE($E$5,MATCH($C$5,Lists!$A$2:$A$13,0),28)) | AJ1: =IF(29>$BA$2,"",DATE($E$5,MATCH($C$5,Lists!$A$2:$A$13,0),29)) | AK1: =IF(30>$BA$2,"",DATE($E$5,MATCH($C$5,Lists!$A$2:$A$13,0),30)) | AL1: =IF(31>$BA$2,"",DATE($E$5,MATCH($C$5,Lists!$A$2:$A$13,0),31)) | AM1: =IF(1>$BA$2,"",DATE($E$5,MATCH($C$5,Lists!$A$2:$A$13,0),1)) | AN1: =IF(2>$BA$2,"",DATE($E$5,MATCH($C$5,Lists!$A$2:$A$13,0),2)) | AO1: =IF(3>$BA$2,"",DATE($E$5,MATCH($C$5,Lists!$A$2:$A$13,0),3)) | AP1: =IF(4>$BA$2,"",DATE($E$5,MATCH($C$5,Lists!$A$2:$A$13,0),4)) | AQ1: =IF(5>$BA$2,"",DATE($E$5,MATCH($C$5,Lists!$A$2:$A$13,0),5)) | AR1: =IF(6>$BA$2,"",DATE($E$5,MATCH($C$5,Lists!$A$2:$A$13,0),6)) | AS1: =IF(7>$BA$2,"",DATE($E$5,MATCH($C$5,Lists!$A$2:$A$13,0),7)) | AT1: =IF(8>$BA$2,"",DATE($E$5,MATCH($C$5,Lists!$A$2:$A$13,0),8)) | AU1: =IF(9>$BA$2,"",DATE($E$5,MATCH($C$5,Lists!$A$2:$A$13,0),9)) | AV1: =IF(10>$BA$2,"",DATE($E$5,MATCH($C$5,Lists!$A$2:$A$13,0),10)) | AW1: =IF(11>$BA$2,"",DATE($E$5,MATCH($C$5,Lists!$A$2:$A$13,0),11)) | AX1: =IF(12>$BA$2,"",DATE($E$5,MATCH($C$5,Lists!$A$2:$A$13,0),12)) | AY1: =IF(13>$BA$2,"",DATE($E$5,MATCH($C$5,Lists!$A$2:$A$13,0),13)) | AZ1: =IF(14>$BA$2,"",DATE($E$5,MATCH($C$5,Lists!$A$2:$A$13,0),14)) | BA1: =IF(15>$BA$2,"",DATE($E$5,MATCH($C$5,Lists!$A$2:$A$13,0),15)) | BB1: =IF(16>$BA$2,"",DATE($E$5,MATCH($C$5,Lists!$A$2:$A$13,0),16)) | BC1: =IF(17>$BA$2,"",DATE($E$5,MATCH($C$5,Lists!$A$2:$A$13,0),17)) | BD1: =IF(18>$BA$2,"",DATE($E$5,MATCH($C$5,Lists!$A$2:$A$13,0),18)) | BE1: =IF(19>$BA$2,"",DATE($E$5,MATCH($C$5,Lists!$A$2:$A$13,0),19)) | BF1: =IF(20>$BA$2,"",DATE($E$5,MATCH($C$5,Lists!$A$2:$A$13,0),20)) | BG1: =IF(21>$BA$2,"",DATE($E$5,MATCH($C$5,Lists!$A$2:$A$13,0),21)) | BH1: =IF(22>$BA$2,"",DATE($E$5,MATCH($C$5,Lists!$A$2:$A$13,0),22)) | BI1: =IF(23>$BA$2,"",DATE($E$5,MATCH($C$5,Lists!$A$2:$A$13,0),23)) | BJ1: =IF(24>$BA$2,"",DATE($E$5,MATCH($C$5,Lists!$A$2:$A$13,0),24)) | BK1: =IF(25>$BA$2,"",DATE($E$5,MATCH($C$5,Lists!$A$2:$A$13,0),25)) | BL1: =IF(26>$BA$2,"",DATE($E$5,MATCH($C$5,Lists!$A$2:$A$13,0),26)) | BM1: =IF(27>$BA$2,"",DATE($E$5,MATCH($C$5,Lists!$A$2:$A$13,0),27)) | BN1: =IF(28>$BA$2,"",DATE($E$5,MATCH($C$5,Lists!$A$2:$A$13,0),28)) | BO1: =IF(29>$BA$2,"",DATE($E$5,MATCH($C$5,Lists!$A$2:$A$13,0),29)) | BP1: =IF(30>$BA$2,"",DATE($E$5,MATCH($C$5,Lists!$A$2:$A$13,0),30)) | BQ1: =IF(31>$BA$2,"",DATE($E$5,MATCH($C$5,Lists!$A$2:$A$13,0),31)) | CA1: =Dashboard!H16 -> 46204 | CB1: =Dashboard!I16 -> 46205 | CC1: =Dashboard!J16 -> 46206 | CD1: =Dashboard!K16 -> 46207 | CE1: =Dashboard!L16 -> 46208 | CF1: =Dashboard!M16 -> 46209 | CG1: =Dashboard!N16 -> 46210 | CH1: =Dashboard!O16 -> 46211 | ... DE1: =Dashboard!AL16 -> 46234
A2: =Dashboard!B20 -> Exercise | B2: =Dashboard!C20 -> High | C2: =Dashboard!D20 -> Health | D2: =Dashboard!E20 -> Weekly | E2: =Dashboard!F20 -> 25 | F2: =Dashboard!G20 -> Morning walk or workout | H2: FALSE | I2: FALSE | J2: FALSE | K2: TRUE | L2: FALSE | M2: FALSE | N2: FALSE | O2: FALSE | P2: FALSE | Q2: FALSE | R2: FALSE | S2: FALSE | T2: FALSE | U2: FALSE | V2: FALSE | W2: FALSE | X2: FALSE | Y2: FALSE | Z2: FALSE | AA2: FALSE | AB2: FALSE | AC2: FALSE | AD2: FALSE | AE2: FALSE | AF2: FALSE | AG2: FALSE | AH2: FALSE | AI2: FALSE | AJ2: FALSE | AK2: FALSE | AL2: FALSE | AM2: =IF(H2=TRUE,1,0) -> 0 | AN2: =IF(I2=TRUE,1,0) -> 0 | AO2: =IF(J2=TRUE,1,0) -> 0 | AP2: =IF(K2=TRUE,1,0) -> 1 | AQ2: =IF(L2=TRUE,1,0) -> 0 | AR2: =IF(M2=TRUE,1,0) -> 0 | AS2: =IF(N2=TRUE,1,0) -> 0 | AT2: =IF(O2=TRUE,1,0) -> 0 | ... BQ2: =IF(AL2=TRUE,1,0) -> 0 | BT2: {=IF(A2="","",MAX(FREQUENCY(IF(AM2:BQ2=1,COLUMN(AM2:BQ2)),IF(AM2:BQ2=0,COLUMN(AM2:BQ2)))))} -> 1 | CA2: =SUM(AM2:AM51) -> 0 | CB2: =SUM(AN2:AN51) -> 0 | CC2: =SUM(AO2:AO51) -> 0 | CD2: =SUM(AP2:AP51) -> 4 | CE2: =SUM(AQ2:AQ51) -> 1 | CF2: =SUM(AR2:AR51) -> 0 | CG2: =SUM(AS2:AS51) -> 0 | CH2: =SUM(AT2:AT51) -> 0 | ... DE2: =SUM(BQ2:BQ51) -> 0
A3: =Dashboard!B21 -> Study | B3: =Dashboard!C21 -> High | C3: =Dashboard!D21 -> Study | D3: =Dashboard!E21 -> Daily | E3: =Dashboard!F21 -> 20 | F3: =Dashboard!G21 -> Interview practice | H3: FALSE | I3: FALSE | J3: FALSE | K3: TRUE | L3: TRUE | N3: FALSE | AM3: =IF(H3=TRUE,1,0) -> 0 | AN3: =IF(I3=TRUE,1,0) -> 0 | AO3: =IF(J3=TRUE,1,0) -> 0 | AP3: =IF(K3=TRUE,1,0) -> 1 | AQ3: =IF(L3=TRUE,1,0) -> 1 | AR3: =IF(M3=TRUE,1,0) -> 0 | AS3: =IF(N3=TRUE,1,0) -> 0 | AT3: =IF(O3=TRUE,1,0) -> 0 | ... BQ3: =IF(AL3=TRUE,1,0) -> 0 | BT3: {=IF(A3="","",MAX(FREQUENCY(IF(AM3:BQ3=1,COLUMN(AM3:BQ3)),IF(AM3:BQ3=0,COLUMN(AM3:BQ3)))))} -> 2 | CA3: =IFERROR(CA2/Dashboard!$B$8,0) -> 0 | CB3: =IFERROR(CB2/Dashboard!$B$8,0) -> 0 | CC3: =IFERROR(CC2/Dashboard!$B$8,0) -> 0 | CD3: =IFERROR(CD2/Dashboard!$B$8,0) -> 1 | CE3: =IFERROR(CE2/Dashboard!$B$8,0) -> 0.25 | CF3: =IFERROR(CF2/Dashboard!$B$8,0) -> 0 | CG3: =IFERROR(CG2/Dashboard!$B$8,0) -> 0 | CH3: =IFERROR(CH2/Dashboard!$B$8,0) -> 0 | ... DE3: =IFERROR(DE2/Dashboard!$B$8,0) -> 0
A4: =Dashboard!B22 -> Read Book | B4: =Dashboard!C22 -> Medium | C4: =Dashboard!D22 -> Habit | D4: =Dashboard!E22 -> Daily | E4: =Dashboard!F22 -> 15 | F4: =Dashboard!G22 -> 15 pages | H4: FALSE | I4: FALSE | J4: FALSE | K4: TRUE | L4: FALSE | AM4: =IF(H4=TRUE,1,0) -> 0 | AN4: =IF(I4=TRUE,1,0) -> 0 | AO4: =IF(J4=TRUE,1,0) -> 0 | AP4: =IF(K4=TRUE,1,0) -> 1 | AQ4: =IF(L4=TRUE,1,0) -> 0 | AR4: =IF(M4=TRUE,1,0) -> 0 | AS4: =IF(N4=TRUE,1,0) -> 0 | AT4: =IF(O4=TRUE,1,0) -> 0 | ... BQ4: =IF(AL4=TRUE,1,0) -> 0 | BT4: {=IF(A4="","",MAX(FREQUENCY(IF(AM4:BQ4=1,COLUMN(AM4:BQ4)),IF(AM4:BQ4=0,COLUMN(AM4:BQ4)))))} -> 1
A5: =Dashboard!B23 -> Call Family | B5: =Dashboard!C23 -> Low | C5: =Dashboard!D23 -> Personal | D5: =Dashboard!E23 -> Weekly | E5: =Dashboard!F23 -> 6 | F5: =Dashboard!G23 -> Stay connected | H5: FALSE | I5: FALSE | K5: TRUE | L5: FALSE | AM5: =IF(H5=TRUE,1,0) -> 0 | AN5: =IF(I5=TRUE,1,0) -> 0 | AO5: =IF(J5=TRUE,1,0) -> 0 | AP5: =IF(K5=TRUE,1,0) -> 1 | AQ5: =IF(L5=TRUE,1,0) -> 0 | AR5: =IF(M5=TRUE,1,0) -> 0 | AS5: =IF(N5=TRUE,1,0) -> 0 | AT5: =IF(O5=TRUE,1,0) -> 0 | ... BQ5: =IF(AL5=TRUE,1,0) -> 0 | BT5: {=IF(A5="","",MAX(FREQUENCY(IF(AM5:BQ5=1,COLUMN(AM5:BQ5)),IF(AM5:BQ5=0,COLUMN(AM5:BQ5)))))} -> 1
A6: =Dashboard!B24 -> 0 | B6: =Dashboard!C24 -> 0 | C6: =Dashboard!D24 -> 0 | D6: =Dashboard!E24 -> 0 | E6: =Dashboard!F24 -> 0 | F6: =Dashboard!G24 -> 0 | J6: FALSE | K6: FALSE | AM6: =IF(H6=TRUE,1,0) -> 0 | AN6: =IF(I6=TRUE,1,0) -> 0 | AO6: =IF(J6=TRUE,1,0) -> 0 | AP6: =IF(K6=TRUE,1,0) -> 0 | AQ6: =IF(L6=TRUE,1,0) -> 0 | AR6: =IF(M6=TRUE,1,0) -> 0 | AS6: =IF(N6=TRUE,1,0) -> 0 | AT6: =IF(O6=TRUE,1,0) -> 0 | ... BQ6: =IF(AL6=TRUE,1,0) -> 0 | BT6: {=IF(A6="","",MAX(FREQUENCY(IF(AM6:BQ6=1,COLUMN(AM6:BQ6)),IF(AM6:BQ6=0,COLUMN(AM6:BQ6)))))} -> 0
A7: =Dashboard!B25 -> 0 | B7: =Dashboard!C25 -> 0 | C7: =Dashboard!D25 -> 0 | D7: =Dashboard!E25 -> 0 | E7: =Dashboard!F25 -> 0 | F7: =Dashboard!G25 -> 0 | AM7: =IF(H7=TRUE,1,0) -> 0 | AN7: =IF(I7=TRUE,1,0) -> 0 | AO7: =IF(J7=TRUE,1,0) -> 0 | AP7: =IF(K7=TRUE,1,0) -> 0 | AQ7: =IF(L7=TRUE,1,0) -> 0 | AR7: =IF(M7=TRUE,1,0) -> 0 | AS7: =IF(N7=TRUE,1,0) -> 0 | AT7: =IF(O7=TRUE,1,0) -> 0 | ... BQ7: =IF(AL7=TRUE,1,0) -> 0 | BT7: {=IF(A7="","",MAX(FREQUENCY(IF(AM7:BQ7=1,COLUMN(AM7:BQ7)),IF(AM7:BQ7=0,COLUMN(AM7:BQ7)))))} -> 0
A8: =Dashboard!B26 -> 0 | B8: =Dashboard!C26 -> 0 | C8: =Dashboard!D26 -> 0 | D8: =Dashboard!E26 -> 0 | E8: =Dashboard!F26 -> 0 | F8: =Dashboard!G26 -> 0 | AM8: =IF(H8=TRUE,1,0) -> 0 | AN8: =IF(I8=TRUE,1,0) -> 0 | AO8: =IF(J8=TRUE,1,0) -> 0 | AP8: =IF(K8=TRUE,1,0) -> 0 | AQ8: =IF(L8=TRUE,1,0) -> 0 | AR8: =IF(M8=TRUE,1,0) -> 0 | AS8: =IF(N8=TRUE,1,0) -> 0 | AT8: =IF(O8=TRUE,1,0) -> 0 | ... BQ8: =IF(AL8=TRUE,1,0) -> 0 | BT8: {=IF(A8="","",MAX(FREQUENCY(IF(AM8:BQ8=1,COLUMN(AM8:BQ8)),IF(AM8:BQ8=0,COLUMN(AM8:BQ8)))))} -> 0
A9: =Dashboard!B27 -> 0 | B9: =Dashboard!C27 -> 0 | C9: =Dashboard!D27 -> 0 | D9: =Dashboard!E27 -> 0 | E9: =Dashboard!F27 -> 0 | F9: =Dashboard!G27 -> 0 | Q9: FALSE | AM9: =IF(H9=TRUE,1,0) -> 0 | AN9: =IF(I9=TRUE,1,0) -> 0 | AO9: =IF(J9=TRUE,1,0) -> 0 | AP9: =IF(K9=TRUE,1,0) -> 0 | AQ9: =IF(L9=TRUE,1,0) -> 0 | AR9: =IF(M9=TRUE,1,0) -> 0 | AS9: =IF(N9=TRUE,1,0) -> 0 | AT9: =IF(O9=TRUE,1,0) -> 0 | ... BQ9: =IF(AL9=TRUE,1,0) -> 0 | BT9: {=IF(A9="","",MAX(FREQUENCY(IF(AM9:BQ9=1,COLUMN(AM9:BQ9)),IF(AM9:BQ9=0,COLUMN(AM9:BQ9)))))} -> 0
A10: =Dashboard!B28 -> 0 | B10: =Dashboard!C28 -> 0 | C10: =Dashboard!D28 -> 0 | D10: =Dashboard!E28 -> 0 | E10: =Dashboard!F28 -> 0 | F10: =Dashboard!G28 -> 0 | AM10: =IF(H10=TRUE,1,0) -> 0 | AN10: =IF(I10=TRUE,1,0) -> 0 | AO10: =IF(J10=TRUE,1,0) -> 0 | AP10: =IF(K10=TRUE,1,0) -> 0 | AQ10: =IF(L10=TRUE,1,0) -> 0 | AR10: =IF(M10=TRUE,1,0) -> 0 | AS10: =IF(N10=TRUE,1,0) -> 0 | AT10: =IF(O10=TRUE,1,0) -> 0 | ... BQ10: =IF(AL10=TRUE,1,0) -> 0 | BT10: {=IF(A10="","",MAX(FREQUENCY(IF(AM10:BQ10=1,COLUMN(AM10:BQ10)),IF(AM10:BQ10=0,COLUMN(AM10:BQ10)))))} -> 0
A11: =Dashboard!B29 -> 0 | B11: =Dashboard!C29 -> 0 | C11: =Dashboard!D29 -> 0 | D11: =Dashboard!E29 -> 0 | E11: =Dashboard!F29 -> 0 | F11: =Dashboard!G29 -> 0 | AM11: =IF(H11=TRUE,1,0) -> 0 | AN11: =IF(I11=TRUE,1,0) -> 0 | AO11: =IF(J11=TRUE,1,0) -> 0 | AP11: =IF(K11=TRUE,1,0) -> 0 | AQ11: =IF(L11=TRUE,1,0) -> 0 | AR11: =IF(M11=TRUE,1,0) -> 0 | AS11: =IF(N11=TRUE,1,0) -> 0 | AT11: =IF(O11=TRUE,1,0) -> 0 | ... BQ11: =IF(AL11=TRUE,1,0) -> 0 | BT11: {=IF(A11="","",MAX(FREQUENCY(IF(AM11:BQ11=1,COLUMN(AM11:BQ11)),IF(AM11:BQ11=0,COLUMN(AM11:BQ11)))))} -> 0
A12: =Dashboard!B30 -> 0 | B12: =Dashboard!C30 -> 0 | C12: =Dashboard!D30 -> 0 | D12: =Dashboard!E30 -> 0 | E12: =Dashboard!F30 -> 0 | F12: =Dashboard!G30 -> 0 | AM12: =IF(H12=TRUE,1,0) -> 0 | AN12: =IF(I12=TRUE,1,0) -> 0 | AO12: =IF(J12=TRUE,1,0) -> 0 | AP12: =IF(K12=TRUE,1,0) -> 0 | AQ12: =IF(L12=TRUE,1,0) -> 0 | AR12: =IF(M12=TRUE,1,0) -> 0 | AS12: =IF(N12=TRUE,1,0) -> 0 | AT12: =IF(O12=TRUE,1,0) -> 0 | ... BQ12: =IF(AL12=TRUE,1,0) -> 0 | BT12: {=IF(A12="","",MAX(FREQUENCY(IF(AM12:BQ12=1,COLUMN(AM12:BQ12)),IF(AM12:BQ12=0,COLUMN(AM12:BQ12)))))} -> 0
A13: =Dashboard!B31 -> 0 | B13: =Dashboard!C31 -> 0 | C13: =Dashboard!D31 -> 0 | D13: =Dashboard!E31 -> 0 | E13: =Dashboard!F31 -> 0 | F13: =Dashboard!G31 -> 0 | AM13: =IF(H13=TRUE,1,0) -> 0 | AN13: =IF(I13=TRUE,1,0) -> 0 | AO13: =IF(J13=TRUE,1,0) -> 0 | AP13: =IF(K13=TRUE,1,0) -> 0 | AQ13: =IF(L13=TRUE,1,0) -> 0 | AR13: =IF(M13=TRUE,1,0) -> 0 | AS13: =IF(N13=TRUE,1,0) -> 0 | AT13: =IF(O13=TRUE,1,0) -> 0 | ... BQ13: =IF(AL13=TRUE,1,0) -> 0 | BT13: {=IF(A13="","",MAX(FREQUENCY(IF(AM13:BQ13=1,COLUMN(AM13:BQ13)),IF(AM13:BQ13=0,COLUMN(AM13:BQ13)))))} -> 0
A14: =Dashboard!B32 -> 0 | B14: =Dashboard!C32 -> 0 | C14: =Dashboard!D32 -> 0 | D14: =Dashboard!E32 -> 0 | E14: =Dashboard!F32 -> 0 | F14: =Dashboard!G32 -> 0 | AM14: =IF(H14=TRUE,1,0) -> 0 | AN14: =IF(I14=TRUE,1,0) -> 0 | AO14: =IF(J14=TRUE,1,0) -> 0 | AP14: =IF(K14=TRUE,1,0) -> 0 | AQ14: =IF(L14=TRUE,1,0) -> 0 | AR14: =IF(M14=TRUE,1,0) -> 0 | AS14: =IF(N14=TRUE,1,0) -> 0 | AT14: =IF(O14=TRUE,1,0) -> 0 | ... BQ14: =IF(AL14=TRUE,1,0) -> 0 | BT14: {=IF(A14="","",MAX(FREQUENCY(IF(AM14:BQ14=1,COLUMN(AM14:BQ14)),IF(AM14:BQ14=0,COLUMN(AM14:BQ14)))))} -> 0
A15: =Dashboard!B33 -> 0 | B15: =Dashboard!C33 -> 0 | C15: =Dashboard!D33 -> 0 | D15: =Dashboard!E33 -> 0 | E15: =Dashboard!F33 -> 0 | F15: =Dashboard!G33 -> 0 | AM15: =IF(H15=TRUE,1,0) -> 0 | AN15: =IF(I15=TRUE,1,0) -> 0 | AO15: =IF(J15=TRUE,1,0) -> 0 | AP15: =IF(K15=TRUE,1,0) -> 0 | AQ15: =IF(L15=TRUE,1,0) -> 0 | AR15: =IF(M15=TRUE,1,0) -> 0 | AS15: =IF(N15=TRUE,1,0) -> 0 | AT15: =IF(O15=TRUE,1,0) -> 0 | ... BQ15: =IF(AL15=TRUE,1,0) -> 0 | BT15: {=IF(A15="","",MAX(FREQUENCY(IF(AM15:BQ15=1,COLUMN(AM15:BQ15)),IF(AM15:BQ15=0,COLUMN(AM15:BQ15)))))} -> 0
A16: =Dashboard!B34 -> 0 | B16: =Dashboard!C34 -> 0 | C16: =Dashboard!D34 -> 0 | D16: =Dashboard!E34 -> 0 | E16: =Dashboard!F34 -> 0 | F16: =Dashboard!G34 -> 0 | AM16: =IF(H16=TRUE,1,0) -> 0 | AN16: =IF(I16=TRUE,1,0) -> 0 | AO16: =IF(J16=TRUE,1,0) -> 0 | AP16: =IF(K16=TRUE,1,0) -> 0 | AQ16: =IF(L16=TRUE,1,0) -> 0 | AR16: =IF(M16=TRUE,1,0) -> 0 | AS16: =IF(N16=TRUE,1,0) -> 0 | AT16: =IF(O16=TRUE,1,0) -> 0 | ... BQ16: =IF(AL16=TRUE,1,0) -> 0 | BT16: {=IF(A16="","",MAX(FREQUENCY(IF(AM16:BQ16=1,COLUMN(AM16:BQ16)),IF(AM16:BQ16=0,COLUMN(AM16:BQ16)))))} -> 0
A17: =Dashboard!B35 -> 0 | B17: =Dashboard!C35 -> 0 | C17: =Dashboard!D35 -> 0 | D17: =Dashboard!E35 -> 0 | E17: =Dashboard!F35 -> 0 | F17: =Dashboard!G35 -> 0 | AM17: =IF(H17=TRUE,1,0) -> 0 | AN17: =IF(I17=TRUE,1,0) -> 0 | AO17: =IF(J17=TRUE,1,0) -> 0 | AP17: =IF(K17=TRUE,1,0) -> 0 | AQ17: =IF(L17=TRUE,1,0) -> 0 | AR17: =IF(M17=TRUE,1,0) -> 0 | AS17: =IF(N17=TRUE,1,0) -> 0 | AT17: =IF(O17=TRUE,1,0) -> 0 | ... BQ17: =IF(AL17=TRUE,1,0) -> 0 | BT17: {=IF(A17="","",MAX(FREQUENCY(IF(AM17:BQ17=1,COLUMN(AM17:BQ17)),IF(AM17:BQ17=0,COLUMN(AM17:BQ17)))))} -> 0
A18: =Dashboard!B36 -> 0 | B18: =Dashboard!C36 -> 0 | C18: =Dashboard!D36 -> 0 | D18: =Dashboard!E36 -> 0 | E18: =Dashboard!F36 -> 0 | F18: =Dashboard!G36 -> 0 | AM18: =IF(H18=TRUE,1,0) -> 0 | AN18: =IF(I18=TRUE,1,0) -> 0 | AO18: =IF(J18=TRUE,1,0) -> 0 | AP18: =IF(K18=TRUE,1,0) -> 0 | AQ18: =IF(L18=TRUE,1,0) -> 0 | AR18: =IF(M18=TRUE,1,0) -> 0 | AS18: =IF(N18=TRUE,1,0) -> 0 | AT18: =IF(O18=TRUE,1,0) -> 0 | ... BQ18: =IF(AL18=TRUE,1,0) -> 0 | BT18: {=IF(A18="","",MAX(FREQUENCY(IF(AM18:BQ18=1,COLUMN(AM18:BQ18)),IF(AM18:BQ18=0,COLUMN(AM18:BQ18)))))} -> 0
A19: =Dashboard!B37 -> 0 | B19: =Dashboard!C37 -> 0 | C19: =Dashboard!D37 -> 0 | D19: =Dashboard!E37 -> 0 | E19: =Dashboard!F37 -> 0 | F19: =Dashboard!G37 -> 0 | AM19: =IF(H19=TRUE,1,0) -> 0 | AN19: =IF(I19=TRUE,1,0) -> 0 | AO19: =IF(J19=TRUE,1,0) -> 0 | AP19: =IF(K19=TRUE,1,0) -> 0 | AQ19: =IF(L19=TRUE,1,0) -> 0 | AR19: =IF(M19=TRUE,1,0) -> 0 | AS19: =IF(N19=TRUE,1,0) -> 0 | AT19: =IF(O19=TRUE,1,0) -> 0 | ... BQ19: =IF(AL19=TRUE,1,0) -> 0 | BT19: {=IF(A19="","",MAX(FREQUENCY(IF(AM19:BQ19=1,COLUMN(AM19:BQ19)),IF(AM19:BQ19=0,COLUMN(AM19:BQ19)))))} -> 0
A20: =Dashboard!B38 -> 0 | B20: =Dashboard!C38 -> 0 | C20: =Dashboard!D38 -> 0 | D20: =Dashboard!E38 -> 0 | E20: =Dashboard!F38 -> 0 | F20: =Dashboard!G38 -> 0 | AM20: =IF(H20=TRUE,1,0) -> 0 | AN20: =IF(I20=TRUE,1,0) -> 0 | AO20: =IF(J20=TRUE,1,0) -> 0 | AP20: =IF(K20=TRUE,1,0) -> 0 | AQ20: =IF(L20=TRUE,1,0) -> 0 | AR20: =IF(M20=TRUE,1,0) -> 0 | AS20: =IF(N20=TRUE,1,0) -> 0 | AT20: =IF(O20=TRUE,1,0) -> 0 | ... BQ20: =IF(AL20=TRUE,1,0) -> 0 | BT20: {=IF(A20="","",MAX(FREQUENCY(IF(AM20:BQ20=1,COLUMN(AM20:BQ20)),IF(AM20:BQ20=0,COLUMN(AM20:BQ20)))))} -> 0
A21: =Dashboard!B39 -> 0 | B21: =Dashboard!C39 -> 0 | C21: =Dashboard!D39 -> 0 | D21: =Dashboard!E39 -> 0 | E21: =Dashboard!F39 -> 0 | F21: =Dashboard!G39 -> 0 | AM21: =IF(H21=TRUE,1,0) -> 0 | AN21: =IF(I21=TRUE,1,0) -> 0 | AO21: =IF(J21=TRUE,1,0) -> 0 | AP21: =IF(K21=TRUE,1,0) -> 0 | AQ21: =IF(L21=TRUE,1,0) -> 0 | AR21: =IF(M21=TRUE,1,0) -> 0 | AS21: =IF(N21=TRUE,1,0) -> 0 | AT21: =IF(O21=TRUE,1,0) -> 0 | ... BQ21: =IF(AL21=TRUE,1,0) -> 0 | BT21: {=IF(A21="","",MAX(FREQUENCY(IF(AM21:BQ21=1,COLUMN(AM21:BQ21)),IF(AM21:BQ21=0,COLUMN(AM21:BQ21)))))} -> 0
... A51: =Dashboard!B69 -> 0 | B51: =Dashboard!C69 -> 0 | C51: =Dashboard!D69 -> 0 | D51: =Dashboard!E69 -> 0 | E51: =Dashboard!F69 -> 0 | F51: =Dashboard!G69 -> 0 | AM51: =IF(H51=TRUE,1,0) -> 0 | AN51: =IF(I51=TRUE,1,0) -> 0 | AO51: =IF(J51=TRUE,1,0) -> 0 | AP51: =IF(K51=TRUE,1,0) -> 0 | AQ51: =IF(L51=TRUE,1,0) -> 0 | AR51: =IF(M51=TRUE,1,0) -> 0 | AS51: =IF(N51=TRUE,1,0) -> 0 | AT51: =IF(O51=TRUE,1,0) -> 0 | ... BQ51: =IF(AL51=TRUE,1,0) -> 0 | BT51: {=IF(A51="","",MAX(FREQUENCY(IF(AM51:BQ51=1,COLUMN(AM51:BQ51)),IF(AM51:BQ51=0,COLUMN(AM51:BQ51)))))} -> 0
A60: Week | B60: Completed | C60: Possible | D60: Progress % | F60: Status | G60: Count
A61: Week 1 | B61: =SUMIFS($CA$2:$DE$2,$CA$1:$DE$1,">="&DATE(Dashboard!$E$5,MATCH(Dashboard!$C$5,Lists!$A$2:$A$13,0),1)+(1-1)*7,$CA$1:$DE$1,"<"&DATE(Dashboard!$E$5,MATCH(Dashboard!$C$5,Lists!$A$2:$A$13,0),1)+1*7) -> 5 | C61: =Dashboard!$B$8*COUNTIFS($CA$1:$DE$1,">="&DATE(Dashboard!$E$5,MATCH(Dashboard!$C$5,Lists!$A$2:$A$13,0),1)+(1-1)*7,$CA$1:$DE$1,"<"&DATE(Dashboard!$E$5,MATCH(Dashboard!$C$5,Lists!$A$2:$A$13,0),1)+1*7) -> 28 | D61: =IFERROR(B61/C61,0) -> 0.17857143 | F61: Completed | G61: =Dashboard!E8 -> 5
A62: Week 2 | B62: =SUMIFS($CA$2:$DE$2,$CA$1:$DE$1,">="&DATE(Dashboard!$E$5,MATCH(Dashboard!$C$5,Lists!$A$2:$A$13,0),1)+(2-1)*7,$CA$1:$DE$1,"<"&DATE(Dashboard!$E$5,MATCH(Dashboard!$C$5,Lists!$A$2:$A$13,0),1)+2*7) -> 0 | C62: =Dashboard!$B$8*COUNTIFS($CA$1:$DE$1,">="&DATE(Dashboard!$E$5,MATCH(Dashboard!$C$5,Lists!$A$2:$A$13,0),1)+(2-1)*7,$CA$1:$DE$1,"<"&DATE(Dashboard!$E$5,MATCH(Dashboard!$C$5,Lists!$A$2:$A$13,0),1)+2*7) -> 28 | D62: =IFERROR(B62/C62,0) -> 0 | F62: Pending | G62: =Dashboard!H8 -> 119
A63: Week 3 | B63: =SUMIFS($CA$2:$DE$2,$CA$1:$DE$1,">="&DATE(Dashboard!$E$5,MATCH(Dashboard!$C$5,Lists!$A$2:$A$13,0),1)+(3-1)*7,$CA$1:$DE$1,"<"&DATE(Dashboard!$E$5,MATCH(Dashboard!$C$5,Lists!$A$2:$A$13,0),1)+3*7) -> 0 | C63: =Dashboard!$B$8*COUNTIFS($CA$1:$DE$1,">="&DATE(Dashboard!$E$5,MATCH(Dashboard!$C$5,Lists!$A$2:$A$13,0),1)+(3-1)*7,$CA$1:$DE$1,"<"&DATE(Dashboard!$E$5,MATCH(Dashboard!$C$5,Lists!$A$2:$A$13,0),1)+3*7) -> 28 | D63: =IFERROR(B63/C63,0) -> 0
A64: Week 4 | B64: =SUMIFS($CA$2:$DE$2,$CA$1:$DE$1,">="&DATE(Dashboard!$E$5,MATCH(Dashboard!$C$5,Lists!$A$2:$A$13,0),1)+(4-1)*7,$CA$1:$DE$1,"<"&DATE(Dashboard!$E$5,MATCH(Dashboard!$C$5,Lists!$A$2:$A$13,0),1)+4*7) -> 0 | C64: =Dashboard!$B$8*COUNTIFS($CA$1:$DE$1,">="&DATE(Dashboard!$E$5,MATCH(Dashboard!$C$5,Lists!$A$2:$A$13,0),1)+(4-1)*7,$CA$1:$DE$1,"<"&DATE(Dashboard!$E$5,MATCH(Dashboard!$C$5,Lists!$A$2:$A$13,0),1)+4*7) -> 28 | D64: =IFERROR(B64/C64,0) -> 0
A65: Week 5 | B65: =SUMIFS($CA$2:$DE$2,$CA$1:$DE$1,">="&DATE(Dashboard!$E$5,MATCH(Dashboard!$C$5,Lists!$A$2:$A$13,0),1)+(5-1)*7,$CA$1:$DE$1,"<"&DATE(Dashboard!$E$5,MATCH(Dashboard!$C$5,Lists!$A$2:$A$13,0),1)+5*7) -> 0 | C65: =Dashboard!$B$8*COUNTIFS($CA$1:$DE$1,">="&DATE(Dashboard!$E$5,MATCH(Dashboard!$C$5,Lists!$A$2:$A$13,0),1)+(5-1)*7,$CA$1:$DE$1,"<"&DATE(Dashboard!$E$5,MATCH(Dashboard!$C$5,Lists!$A$2:$A$13,0),1)+5*7) -> 12 | D65: =IFERROR(B65/C65,0) -> 0
A66: Week 6 | B66: =SUMIFS($CA$2:$DE$2,$CA$1:$DE$1,">="&DATE(Dashboard!$E$5,MATCH(Dashboard!$C$5,Lists!$A$2:$A$13,0),1)+(6-1)*7,$CA$1:$DE$1,"<"&DATE(Dashboard!$E$5,MATCH(Dashboard!$C$5,Lists!$A$2:$A$13,0),1)+6*7) -> 0 | C66: =Dashboard!$B$8*COUNTIFS($CA$1:$DE$1,">="&DATE(Dashboard!$E$5,MATCH(Dashboard!$C$5,Lists!$A$2:$A$13,0),1)+(6-1)*7,$CA$1:$DE$1,"<"&DATE(Dashboard!$E$5,MATCH(Dashboard!$C$5,Lists!$A$2:$A$13,0),1)+6*7) -> 0 | D66: =IFERROR(B66/C66,0) -> 0

Sheet Lists
A1: Month | B1: Month_No | D1: Year | F1: Priority | H1: Category | J1: Frequency | L1: Status | N1: Quotes
A2: January | B2: 1 | D2: 2024 | F2: High | H2: Study | J2: Daily | L2: TRUE | N2: Small steps every day.
A3: February | B3: 2 | D3: 2025 | F3: Medium | H3: Health | J3: Weekly | L3: FALSE | N3: Progress, not perfection.
A4: March | B4: 3 | D4: 2026 | F4: Low | H4: Work | J4: Custom | N4: Your future self is watching.
A5: April | B5: 4 | D5: 2027 | H5: Personal | N5: Consistency beats intensity.
A6: May | B6: 5 | D6: 2028 | H6: Finance | N6: Win the day, one checkbox at a time.
A7: June | B7: 6 | D7: 2029 | H7: Habit | N7: Make today count.
A8: July | B8: 7 | D8: 2030 | H8: Other | N8: Focus on the next right action.
A9: August | B9: 8 | D9: 2031
A10: September | B10: 9
A11: October | B11: 10
A12: November | B12: 11
A13: December | B13: 12

Sheet Settings
A1: Setting | B1: Value
A2: Card Color | B2: #FFFFFF
A3: Completed Color | B3: #D8F3DC
A4: Missed Color | B4: #FFD6D6
A5: Future Color | B5: #F2F2F2
A6: Weekend Color | B6: #BDE0FE
A7: Today Color | B7: #FFF2B8
A8: Accent Lavender | B8: #CDB4DB
A9: Accent Peach | B9: #FFD6A5
A10: Accent Pink | B10: #FFC8DD
A11: Accent Mint | B11: #D8F3DC
A12: Accent Sky | B12: #BDE0FE
A13: Font | B13: Aptos / Segoe UI / Calibri
